Workbook

Sheet Key ID1
A1: Questions | B1: Latent Variable
A3: Qu1 | B3: Name
A4: Qu2 | B4: Occuption/Role
A5: Qu3 | B5: Email Address
A6: Qu4 | B6: How many people report to you?
A7: Qu5 | B7: Telephone Number
A8: Qu6 | B8: Name of Organisation
A9: Qu7 | B9: How long have you been this organisation for?
A10: Qu8 | B10: Who do you report to?
A11: Qu9 | B11: What is your age?
A12: Qu10 | B12: What is your educational qualification?
A13: Qu11 | B13: How many years of experience do you have in the financial industry
A14: Qu12 | B14: Categorize your Bank in terms of size
A15: Questions | B15: Latent Variable | D15: Strongly Agree | E15: Agree | F15: Somewhat Agree | G15: Neutral | H15: Somewhat Disagree | I15: Disagree | J15: StronglyDisagree
D16: 1 | E16: 2 | F16: 3 | G16: 4 | H16: 5 | I16: 6 | J16: 7
A17: Qu13 | B17: Section A | C17: This bank can be characterised as possessing an adequate risk management framework
A18: Qu14 | C18: Current bank governance policies priorities the need of stakeholders (i.e. government, creditors, depositors, taxpayers)
A19: Qu15 | C19: Outsiders' (e.g investor) and other stakeholders' (e.g. government, creditors, depositors, taxpayers) have influence over senior management
A20: Qu16 | C20: Managers in this bank tend to stair towards risk adverse investment
A21: Qu17 | C21: The board is capable of solving complex issues which is represented in management activities of this bank
A22: Qu18 | C22: Members of the boards of the Directors in this bank are financial experts
A23: Qu19 | C23: This bank exhibits proper risk management departments and possesses a Chief Risk Officer that report to the board
A24: Qu20 | C24: The audit committee board rather than board is responsible for this banks risk management function
A25: Qu21 | C25: The audit committees in this banks may not posses the adequate expertise to interpret complex risk management issues in the banking industry
A26: Qu22 | C26: The audit committees in this banks is subject to undue influence by executive management
A27: Qu23 | C27: Do you have any general comments on any issues raised in this session? (Optional)
A28: Questions | B28: Latent Variable | D28: Strongly Agree | E28: Agree | F28: Somewhat Agree | G28: Neutral | H28: Somewhat Disagree | I28: Disagree | J28: StronglyDisagree
D29: 1 | E29: 2 | F29: 3 | G29: 4 | H29: 5 | I29: 6 | J29: 7
A30: Qu24 | B30: Section B | C30: This bank is characterised by lack of information transparency
A31: Qu25 | C31: There are falsification of financial statements to regulatory authorities in this this bank
A32: Qu26 | C32: It is challenging for this banks to implement effective corporate governance mechanisms to mitigate the risk.
A33: Qu27 | C33: The Board of Directors lack monitoring and oversight of this banks' managers
A34: Qu28 | C34: This banks' directors is characterised with lack of expertise
A35: Qu29 | C35: This banks' directors is characterised with lack of expertise due to influence by the concentrated ownership structures of this banks shareholders
A36: Qu30 | C36: Unjust enrichment is prevalent through the use of Special Purpose Vehicles (SPV) to misuse depositors' funds
A37: Qu31 | C37: Managers engage in self-interested behaviour that may be detrimental to the survival of this bank
A38: Qu32 | C38: Adverse selection of borrowers is a feature of this bank
A39: Qu33 | C39: This Bank attempts to lure consumers away from competitors by offering lower interest rates, leading to an overall decrease in the quality of the loan portfolio
A40: Qu34 | C40: Do you have any general comments on any issues raised in this session? (Optional)
A41: Questions | B41: Latent Variable | D41: Strongly Agree | E41: Agree | F41: Somewhat Agree | G41: Neutral | H41: Somewhat Disagree | I41: Disagree | J41: StronglyDisagree
...

Sheet Data
F1: Name | G1: Role | H1: Email address | I1: report | J1: telephone | K1: Organization | L1: Organization for | M1: report to | N1: Age | O1: qualification | P1: industry | Q1: size | R1: framework | S1: need of stokeholders | T1: other stokeholder | U1: investment | V1: bank | W1: experts | X1: board | Y1: function | Z1: industry | AA1: executive | AB1: session | AC1: transparency | AD1: bank | AE1: risk | AF1: managers | AG1: expertise | AH1: shareholders | AI1: funds | AJ1: bank | AK1: bank | AL1: portfolio | AM1: session | AN1: bank | AO1: regulations | AP1: scenarios | AQ1: needs | AR1: country | AS1: industry | AT1: do not | AU1: board | AV1: board | AW1: board | AX1: transparent | AY1: practices | AZ1: why | BA1: how | BB1: have | BC1: committess | BD1: board | BE1: company | BF1: session
A2: id | B2: age | C2: sex | D2: race | E2: Drive link | F2: qu1 | G2: qu2 | H2: qu3 | I2: qu4 | J2: qu5 | K2: qu6 | L2: qu7 | M2: qu8 | N2: qu9 | O2: qu10 | P2: qu11 | Q2: qu12 | R2: qu13 | S2: qu14 | T2: qu15 | U2: qu16 | V2: qu17 | W2: qu18 | X2: qu19 | Y2: qu20 | Z2: qu21 | AA2: qu22 | AB2: qu23 | AC2: qu24 | AD2: qu25 | AE2: qu26 | AF2: qu27 | AG2: qu28 | AH2: qu29 | AI2: qu30 | AJ2: qu31 | AK2: qu32 | AL2: qu33 | AM2: qu34 | AN2: qu35 | AO2: qu36 | AP2: qu37 | AQ2: qu38 | AR2: qu39 | AS2: qu40 | AT2: qu41 | AU2: qu42 | AV2: qu43 | AW2: qu44 | AX2: qu45 | AY2: qu46 | AZ2: qu47 | BA2: qu48 | BB2: qu49 | BC2: qu50 | BD2: qu51 | BE2: qu52 | BF2: qu53 | BG2: TotalScore
A3: 1 | B3: 49 | C3: Male | D3: White | E3: https://drive.google.com/file/d/1SzQpU-GBDh9NQXRQCviozvk0aTvXbauj/view?usp=sharing | G3: Banker | K3: Keystone Bank | L3: 8 years | M3: Branch Manager | N3: 42 years | O3: Degree plus professional certificates | P3: 9 years | Q3: Large (Between $xx and $xx) | R3: Strongly Agree | S3: Somewhat Agree | T3: Somewhat Agree | U3: Agree | V3: Agree | W3: Agree | X3: Agree | Y3: Agree | Z3: Agree | AA3: Agree | AC3: StronglyDisagree | AD3: Disagree | AE3: Disagree | AF3: Disagree | AG3: Disagree | AH3: Disagree | AI3: StronglyDisagree | AJ3: Disagree | AK3: Disagree | AL3: Disagree | AN3: StronglyAgree | AO3: StronglyDisagree | AP3: Somewhat Agree | AQ3: Agree | AR3: Neutral | AS3: Neutral | AT3: Somewhat Agree | AZ3: No | BB3: 5 | BD3: CEO | BE3: The largest sharaholders hes substantial voting right [for example above 35%) effectively controlling the company | BF3: No | BG3: 54
A4: 2 | B4: 52 | C4: Female | D4: White | E4: https://drive.google.com/file/d/1jzXgC_tUgQJavEgaW-YID0nIicFFzntr/view?usp=drive_link | G4: Banker / Customer | I4: None | K4: Zenith Bank | L4: 3 years | M4: Supervisor | N4: 28 years | O4: HND holder | P4: 3 years | Q4: Large (Between $xx and $xx) | R4: Strongly Agree | S4: Somewhat Agree | T4: Somewhat Disagree | U4: Disagree | V4: Agree | W4: Strongly Agree | X4: Strongly Agree | Y4: Somewhat Agree | Z4: Disagree | AA4: Somewhat Disagree | AB4: No | AC4: Disagree | AD4: Strongly Disagree | AE4: Somewhat Disagree | AF4: Strongly Disagree | AG4: Strongly Disagree | AH4: Disagree | AI4: Disagree | AJ4: Disagree | AK4: Somewhat Disagree | AL4: Somewhat Disagree | AM4: No | AN4: StronglyAgree | AO4: Somewhat Disagree | AP4: Agree | AQ4: Agree | AR4: Somewhat Disagree | AS4: Neutral | AT4: Neutral | AU4: 12 | AV4: 4 | AW4: 8 | AX4: Extremely High | AY4: Extremely High | AZ4: No | BB4: 5 | BC4: Jnn Ovia, Dame Adata, henry Orah, Adobi Ncopa | BD4: CEO | BE4: The largest sharaholders hes substantial voting right [for example above 35%) effectively controlling the company | BF4: No | BG4: 55
A5: 3 | B5: 31 | C5: Male | D5: Hispanic | E5: https://drive.google.com/file/d/19FpyhHdq2GSg1lECRpfSpgD0wmFT1tZr/view?usp=drive_link | G5: Banker / sales rep | I5: 7 | K5: United Bank for Africa | L5: 5 years | M5: Manager | N5: 33 years | O5: Degree holder | P5: 5 years | Q5: Large (Between $xx and $xx) | R5: Strongly Agree | S5: Somewhat Agree | T5: Somewhat Disagree | U5: Somewhat Disagree | V5: Agree | W5: Strongly Agree | X5: Agree | Y5: Somewhat Agree | Z5: Somewhat Disagree | AA5: Somewhat Disagree | AB5: No | AC5: Strongly Disagree | AD5: Strongly Disagree | AE5: Somewhat Disagree | AF5: Disagree | AG5: Strongly Disagree | AH5: Somewhat Disagree | AI5: Disagree | AJ5: Disagree | AK5: Somewhat Disagree | AL5: Somewhat Disagree | AM5: No | AN5: StronglyAgree | AO5: Disagree | AP5: StronglyAgree | AQ5: Agree | AR5: Neutral | AS5: Neutral | AT5: Neutral | AU5: 6 | AV5: 4 | AW5: 4 | AX5: Extremely High | AY5: High | AZ5: No | BB5: 5 | BD5: CEO | BE5: The largest sharaholders hes substantial voting right [for example above 35%) effectively controlling the company | BF5: No | BG5: 58
A6: 4 | B6: 28 | C6: Male | D6: Black | E6: https://drive.google.com/file/d/1iiAn9IETN4EZ1mTdLuBNn6RmVhx7cTFu/view?usp=drive_link | G6: Banker | I6: None | K6: UBA | L6: 5 years | M6: Supervisor | N6: 28 years | O6: HND holder | P6: 5 years | Q6: Large (Between $xx and $xx) | R6: Strongly Agree | S6: Somewhat Agree | T6: Somewhat Disagree | U6: Disagree | V6: Strongly Agree | W6: Strongly Agree | X6: Strongly Agree | Y6: Somewhat Disagree | Z6: Strongly Disagree | AA6: Somewhat Disagree | AB6: No | AC6: Disagree | AD6: Disagree | AE6: Somewhat Disagree | AF6: Strongly Disagree | AG6: Strongly Disagree | AH6: Somewhat Disagree | AI6: Disagree | AJ6: Somewhat Disagree | AK6: Disagree | AL6: Disagree | AM6: No | AN6: StronglyAgree | AO6: Disagree | AP6: StronglyAgree | AQ6: Agree | AR6: Neutral | AS6: Somewhat Disagree | AT6: Neutral | AU6: 12 | AV6: 6 | AW6: 4 | AX6: Extremely High | AY6: High | AZ6: No | BB6: 4 | BD6: CEO | BE6: The largest sharaholders hes substantial voting right [for example above 35%) effectively controlling the company | BF6: No | BG6: 62
A7: 5 | B7: 29 | C7: Male | D7: White | E7: https://drive.google.com/file/d/14NfNkcnJxekTz1-U25ccnTT6bTvhl01-/view?usp=drive_link | G7: Banker | I7: None | K7: Zenith Bank | L7: 5 years | M7: Head of Sales | N7: 32 years | O7: HND holder | P7: 5 years | Q7: Large (Between $xx and $xx) | R7: Strongly Agree | S7: Somewhat Agree | T7: Somewhat Disagree | U7: Disagree | V7: Strongly Agree | W7: Strongly Agree | X7: Strongly Agree | Y7: Somewhat Disagree | Z7: Disagree | AA7: Somewhat Disagree | AC7: Strongly Disagree | AD7: Disagree | AE7: Somewhat Disagree | AF7: Strongly Disagree | AG7: Strongly Disagree | AH7: Disagree | AI7: Somewhat Disagree | AJ7: Somewhat Disagree | AK7: Disagree | AL7: Somewhat Disagree | AM7: No | AN7: StronglyAgree | AO7: Disagree | AP7: StronglyAgree | AQ7: Somewhat Agree | AR7: Somewhat Disagree | AS7: Neutral | AT7: Neutral | AU7: 4 | AV7: 4 | AW7: 4 | AX7: Extremely High | AY7: Extremely High | AZ7: No | BB7: 4 | BD7: CEO | BE7: The largest sharaholders hes substantial voting right [for example above 35%) effectively controlling the company | BF7: No | BG7: 62
A8: 6 | B8: 50 | C8: Female | D8: Black | E8: https://drive.google.com/file/d/1fhly88QZnvHzPzfYX8_gJv5wZCLwmOAi/view?usp=drive_link | G8: Banker / Cashier | I8: None | K8: UBA | L8: 3 years | M8: Supervisor | N8: 26 years | O8: HND holder | P8: 3 years | Q8: Large (Between $xx and $xx) | R8: Agree | S8: Neutral | T8: Somewhat Disagree | U8: Disagree | V8: Agree | W8: Strongly Agree | X8: Agree | Y8: Neutral | Z8: Disagree | AA8: Disagree | AB8: No | AC8: StronglyDisagree | AD8: Disagree | AE8: Disagree | AF8: Disagree | AG8: Strongly Disagree | AH8: Somewhat Disagree | AI8: Somewhat Disagree | AJ8: Disagree | AK8: Disagree | AL8: Somewhat Disagree | AM8: No | AN8: StronglyAgree | AO8: Disagree | AP8: Agree | AQ8: Agree | AR8: Neutral | AS8: Neutral | AT8: Neutral | AU8: 4 | AV8: 4 | AW8: 4 | AX8: Extremely High | AY8: High | AZ8: No | BB8: 4 | BC8: Anthony Elumelu, Oluseyi Alawode, Alex Akpese, Muyiwa Akinyemi, Mustapha Atola | BD8: CEO | BE8: The largest sharaholders hes substantial voting right [for example above 35%) effectively controlling the company | BF8: No | BG8: 54
A9: 7 | B9: 31 | C9: Female | D9: White | E9: https://drive.google.com/file/d/1fz6POEMk-BsyshJxMKdLIqGS-y5Sizx7/view?usp=drive_link | G9: Banker / Sales Rep | I9: None | K9: Zenith Bank | L9: 8 years | M9: Operation Manager | N9: 33 years | O9: Degree holder | P9: 8 years | Q9: Large (Between $xx and $xx) | R9: Strongly Agree | S9: Somewhat Agree | T9: Somewhat Disagree | U9: Disagree | V9: Strongly Agree | W9: Strongly Agree | X9: Strongly Agree | Y9: Somewhat Agree | Z9: Somewhat Disagree | AA9: Disagree | AB9: No | AC9: StronglyDisagree | AD9: Disagree | AE9: Somewhat Disagree | AG9: Strongly Disagree | AH9: Strongly Disagree | AI9: Disagree | AJ9: Somewhat Disagree | AK9: Disagree | AL9: Disagree | AM9: No | AU9: 12 | AV9: 8 | AW9: 4 | AX9: Extremely High | AY9: Extremely High | AZ9: No | BB9: 12 | BD9: CEO | BE9: The largest sharaholders hes substantial voting right [for example above 35%) effectively controlling the company | BF9: No | BG9: 49
A10: 8 | B10: 24 | C10: Female | D10: Black | E10: https://drive.google.com/file/d/1nVJYcrhk4-grQEpsZ5cpUr9N-Xrjjocz/view?usp=drive_link | G10: Banker | I10: 2 | K10: Fidelity Bank | L10: 4 years | M10: Supervisor / Manager | N10: 37 years | O10: Degree holder | P10: 6 years | Q10: Large (Between $xx and $xx) | R10: Strongly Agree | S10: Agree | T10: Somewhat Disagree | U10: Disagree | V10: Strongly Agree | W10: Strongly Agree | X10: Agree | Y10: Somewhat Agree | Z10: Disagree | AA10: Disagree | AB10: No | AC10: StronglyDisagree | AD10: Disagree | AE10: Disagree | AF10: Strongly Disagree | AG10: Strongly Disagree | AH10: Strongly Disagree | AI10: Disagree | AJ10: StronglyDisagree | AK10: Somewhat Disagree | AL10: Disagree | AM10: No | AN10: StronglyAgree | AO10: Somewhat Disagree | AP10: StronglyAgree | AQ10: Agree | AR10: Somewhat Disagree | AS10: Neutral | AT10: Neutral | AU10: 12 | AV10: 4 | AW10: 6 | AX10: Extremely High | AY10: High | AZ10: No | BD10: CEO | BE10: The largest sharaholders hes substantial voting right [for example above 35%) effectively controlling the company | BF10: No | BG10: 64
A11: 9 | B11: 32 | C11: Female | D11: Black | E11: https://drive.google.com/file/d/1JOGDKhh9ccjIu1LHkxYX6B51d-E_2Jgt/view?usp=drive_link | F11: Enice Surname (the surname is not clearly legible). | G11: Head Guard | I11: 10 | J11: 0835423361 | K11: UBA | L11: 17 years | M11: Head of Security | N11: 37 years | P11: 11 years | Q11: Medium (Between $xx and $xx) | R11: Agree | S11: Neutral | T11: Disagree | U11: Agree | V11: Agree | W11: Strongly Agree | X11: Agree | Y11: Agree | Z11: Agree | AA11: Agree | AC11: Disagree | AD11: Agree | AE11: Strongly Disagree | AF11: Disagree | AG11: Disagree | AH11: Neutral | AI11: Disagree | AJ11: Agree | AK11: Agree | AL11: Agree | AM11: No | AN11: Agree | AO11: Disagree | AP11: Agree | AQ11: Disagree | AR11: Agree | AS11: Agree | AT11: Neutral | AU11: 6 | AV11: 3 | AW11: 3 | AX11: High | AY11: High | AZ11: Capacity | BB11: 4 | BC11: Manager | BD11: CEO | BE11: The largest sharaholders hes substantial voting right [for example above 35%) effectively controlling the company | BF11: No | BG11: 66
A12: 10 | B12: 33 | C12: Female | D12: White | E12: https://drive.google.com/file/d/1U-fKXCdwbYKETkSD1yug7OVlrNz914qm/view?usp=drive_link | F12: Enric Dechirygle | G12: Head Lead | I12: 4 | J12: 08135423361 | K12: UBA | L12: 11 years | M12: Head of Operations | N12: 37 years | P12: 11 years | Q12: Medium (Between $xx and $xx) | R12: Agree | S12: Neutral | T12: Disagree | U12: Agree | V12: Agree | W12: Strongly Agree | X12: Agree | Y12: Agree | Z12: Agree | AA12: Agree | AC12: Disagree | AD12: Agree | AE12: Strongly Disagree | AF12: Disagree | AG12: Disagree | AH12: Neutral | AI12: Disagree | AJ12: Agree | AK12: Disagree | AL12: Agree | AM12: No | AN12: Agree | AO12: Disagree | AP12: Agree | AQ12: Disagree | AR12: Agree | AS12: Agree | AT12: Neutral | AU12: 6 | AV12: 3 | AW12: 3 | AX12: Extremely High | AY12: High | AZ12: Capacity | BB12: 4 | BC12: Manager | BE12: The largest sharaholders hes substantial voting right [for example above 35%) effectively controlling the company | BF12: No | BG12: 59
A13: 11 | B13: 46 | C13: Female | D13: White | E13: https://drive.google.com/file/d/1J5L6SqQ0gGmkaYLs5PAqOe1hfL6akPyj/view?usp=drive_link | F13: Alexander Jack Obum | G13: Banker / Sales | J13: 08177433803 | K13: Keystone Bank | L13: 2 years | M13: Branch Manager | N13: 29 years | O13: Degree holder | P13: 2 years | Q13: Medium (Between $xx and $xx) | R13: Strongly Agree | S13: Strongly Agree | T13: Agree | U13: Neutral | V13: Agree | W13: Strongly Agree | X13: Agree | Y13: Agree | Z13: Neutral | AA13: Neutral | AC13: Disagree | AD13: Disagree | AE13: Disagree | AF13: Disagree | AG13: Disagree | AH13: Disagree | AI13: Strongly Disagree | AJ13: Strongly Disagree | AK13: Disagree | AL13: Disagree | AO13: StronglyAgree | AP13: StronglyAgree | AQ13: Neutral | AR13: Neutral | AS13: Somewhat Disagree | AT13: Somewhat Disagree | AX13: High | AY13: High | AZ13: No | BD13: CEO | BE13: The largest sharaholders hes substantial voting right [for example above 35%) effectively controlling the company | BF13: No | BG13: 59
A14: 12 | B14: 39 | C14: Female | D14: White | E14: https://drive.google.com/file/d/1A8iBRkOjGU2LJLgKSev8NQKdtgwnCYE5/view?usp=drive_link | F14: Ubaka Chukwunonso | G14: Banking | H14: rolandubaka@gmail.com | J14: 08137790630 | K14: Keystone Bank Ltd | L14: 2 years | M14: The branch manager | O14: Degree holder | P14: 2 years | Q14: Large (Between $xx and $xx) | R14: Agree | S14: Agree | T14: Neutral | U14: Neutral | V14: Agree | W14: Agree | X14: Agree | Y14: Agree | Z14: Disagree | AA14: Somewhat Disagree | AB14: None | AC14: Disagree | AD14: Strongly Disagree | AE14: Somewhat Disagree | AF14: Strongly Disagree | AG14: Strongly Disagree | AH14: Disagree | AI14: Disagree | AJ14: Strongly Disagree | AK14: Neutral | AL14: Somewhat Disagree | AM14: None | AN14: StronglyAgree | AO14: Somewhat Agree | AP14: Agree | AQ14: Agree | AR14: Neutral | AS14: Neutral | AT14: Somewhat Disagree | AU14: 3 | AV14: 3 | AX14: High | AY14: High | AZ14: No | BB14: 1 | BD14: CEO | BE14: The largest sharaholders hes substantial voting right [for example above 35%) effectively controlling the company | BG14: 84
A15: 13 | B15: 46 | C15: Male | D15: Black | E15: https://drive.google.com/file/d/1UUgJmKC8uljsYGhTKh9Sj_Mbr9csOo9k/view?usp=drive_link | F15: Raphael Ogeth | G15: Banker / Teller | H15: Nil | I15: Nil | J15: 07084110097 | K15: UBA | L15: 6 years | M15: Branch Manager | N15: 37 years | O15: Degree holder | P15: 1 years | R15: Strongly Agree | S15: Agree | T15: Neutral | U15: Neutral | V15: Strongly Agree | W15: Strongly Agree | X15: Strongly Agree | Y15: Neutral | Z15: Somewhat Disagree | AA15: Disagree | AC15: Disagree | AD15: Strongly Disagree | AE15: Disagree | AF15: Disagree | AG15: Strongly Disagree | AH15: Disagree | AI15: Disagree | AJ15: Disagree | AK15: Disagree | AL15: Disagree | AN15: StronglyAgree | AO15: Somewhat Agree | AP15: Agree | AQ15: Somewhat Agree | AR15: Somewhat Agree | AS15: Neutral | AT15: Somewhat Agree | BG15: 58
A16: 14 | B16: 41 | C16: Male | D16: White | E16: https://drive.google.com/file/d/1nUldy0qGlfuNg8yzGiZqJvF4ckIcWHMG/view?usp=drive_link | G16: Banker / Customer care | I16: None | K16: UBA | L16: 4 years | M16: Supervisor | N16: 38 years | O16: Degree holder | Q16: Large (Between $xx and $xx) | R16: Agree | S16: Agree | T16: Agree | U16: Agree | V16: Agree | W16: Somewhat Agree | X16: Strongly Agree | Y16: Somewhat Agree | Z16: Somewhat Agree | AA16: Disagree | AC16: Disagree | AD16: Strongly Disagree | AE16: Disagree | AF16: Disagree | AG16: Strongly Disagree | AH16: Disagree | AI16: Strongly Disagree | AJ16: Disagree | AK16: Disagree | AL16: Strongly Agree | AN16: StronglyAgree | AO16: Disagree | AP16: Agree | AQ16: Somewhat Agree | AR16: Somewhat Agree | AS16: Somewhat Agree | AT16: Somewhat Agree | AU16: 10 | AX16: Extremely High | AY16: High | AZ16: No | BB16: 4 | BD16: CEO | BF16: No | BG16: 63
A17: 15 | B17: 28 | C17: Female | D17: Black | E17: https://drive.google.com/file/d/1X_sHh84OWRsEIP4jyT3BZdiNrLaTXUl1/view?usp=drive_link | F17: John Paul | G17: Bank / Cashier | H17: johnpaul@gmail.com | I17: None | J17: 08169973581 | K17: Eco Bank | L17: 6 years | M17: Operation Manager | N17: 30 years | O17: Degree holder | P17: 6 years | Q17: Large (Between $xx and $xx) | R17: Strongly Agree | S17: Somewhat Agree | T17: Somewhat Disagree | U17: Disagree | V17: Strongly Agree | W17: Strongly Agree | X17: Strongly Agree | Y17: Somewhat Disagree | Z17: Somewhat Disagree | AA17: Disagree | AB17: No | AC17: Strongly Disagree | AD17: Strongly Disagree | AE17: Disagree | AF17: Disagree | AG17: Strongly Disagree | AH17: Disagree | AI17: Disagree | AJ17: Somewhat Disagree | AK17: Disagree | AL17: Disagree | AM17: No | AN17: StronglyAgree | AO17: Somewhat Disagree | AP17: StronglyAgree | AQ17: Agree | AR17: Somewhat Disagree | AS17: Neutral | AT17: Neutral | AU17: 12 | AV17: 4 | AW17: 4 | AX17: Extremely High | AY17: Extremely High | AZ17: No | BB17: 4 | BD17: CEO | BE17: The largest sharaholders hes substantial voting right [for example above 35%) effectively controlling the company | BF17: No | BG17: 56
A18: 16 | B18: 37 | C18: Male | D18: White | E18: https://drive.google.com/file/d/1JLf_ucCMIj1Z46kaArZ2W3EuSFihWV7O/view?usp=drive_link | F18: Raphael Ogeth | G18: Banker / Teller | H18: Nil | I18: Nil | J18: 07084110097 | K18: UBA | L18: 6 years | M18: Branch Manager | N18: 37 years | O18: HND holder | P18: 11 years | Q18: Large (Between $xx and $xx) | R18: Agree | S18: Somewhat Agree | T18: Somewhat Agree | U18: Somewhat Disagree | V18: Agree | W18: Agree | X18: Agree | Y18: Somewhat Agree | Z18: Somewhat Disagree | AA18: Neutral | AB18: No | AC18: Somewhat Disagree | AD18: Disagree | AE18: Somewhat Disagree | AF18: Somewhat Disagree | AG18: Disagree | AH18: Somewhat Disagree | AI18: Somewhat Disagree | AJ18: Somewhat Disagree | AK18: Somewhat Disagree | AL18: Neutral | AM18: No | AN18: Agree | AO18: Disagree | AP18: Somewhat Agree | AQ18: Agree | AR18: Neutral | AS18: Neutral | AT18: Somewhat Disagree | AU18: 8 | AV18: 4 | AW18: 4 | AX18: Extremely High | AY18: Extremely High | AZ18: No | BB18: 4 | BC18: Tony Richards | BD18: CEO | BE18: The largest sharaholders hes substantial voting right [for example above 35%) effectively controlling the company | BG18: 45
A19: 17 | B19: 32 | C19: Female | D19: White | E19: https://drive.google.com/file/d/1L3pqy4OYfwV4RUP9OA8cD6CH6EJ_G_qS/view?usp=drive_link | F19: Adeokun Mohammed | G19: Banker | H19: kmohammed22@gmail.com | I19: 20 | J19: 08035229265 | K19: First Bank | L19: 16 years | M19: Branch Bank Manager | N19: 45 years | O19: Degree holder | Q19: Large (Between $xx and $xx) | R19: Agree | S19: Agree | T19: Somewhat Agree | U19: Neutral | V19: Agree | W19: Agree | X19: Agree | Y19: Neutral | Z19: Disagree | AA19: Disagree | AB19: No | AC19: Disagree | AD19: Disagree | AE19: Somewhat Disagree | AF19: Disagree | AG19: Strongly Disagree | AH19: Strongly Disagree | AI19: Neutral | AJ19: Neutral | AK19: Neutral | AL19: Disagree | AM19: No | AN19: Agree | AO19: Neutral | AP19: Agree | AQ19: Neutral | AR19: Somewhat Disagree | AS19: Somewhat Disagree | AT19: Somewhat Disagree | AU19: 3 | AV19: 3 | AX19: Extremely High | AY19: High | AZ19: No | BB19: 1 | BD19: CEO | BE19: The largest sharaholders hes substantial voting right [for example above 35%) effectively controlling the company | BF19: No | BG19: 62
A20: 18 | B20: 48 | C20: Female | D20: White | E20: https://drive.google.com/file/d/1Fjh3aBAsg3yJAq-njT44B6uiPZiU0wbq/view?usp=drive_link | F20: Adeokun Muhammed | G20: Banker | H20: kmohammed22@gmail.com | I20: 20 | J20: 08035229265 | K20: First Bank | L20: 16 years | M20: BM (Branch Manager) | N20: 45 years | O20: Degree plus professional certificates | P20: 15 years | Q20: Large (Between $xx and $xx) | R20: Agree | S20: Agree | T20: Somewhat Agree | U20: Somewhat Agree | V20: Agree | W20: Agree | X20: Strongly Agree | Y20: Strongly Agree | Z20: Neutral | AA20: Somewhat Disagree | AB20: No | AC20: Strongly Disagree | AD20: Disagree | AE20: Disagree | AF20: Disagree | AG20: Strongly Disagree | AH20: Disagree | AI20: Neutral | AJ20: Neutral | AK20: Somewhat Disagree | AL20: Neutral | AM20: No | AN20: Agree | AO20: Somewhat Disagree | AP20: StronglyAgree | AQ20: Agree | AR20: Agree | AS20: Agree | AT20: Neutral | AU20: 3 | AV20: 3 | AW20: 3 | AX20: Extremely High | AY20: High | AZ20: No | BD20: CEO | BE20: The largest sharaholders hes substantial voting right [for example above 35%) effectively controlling the company | BF20: No | BG20: 48
A21: 19 | B21: 30 | C21: Female | D21: White | E21: https://drive.google.com/file/d/1zqLbo20w90eg5XUJk1MocMdZg0hZdb4R/view?usp=drive_link | F21: Hassen Morick | G21: Banker / Customer | H21: morickhassen@yahoo.com | I21: None | J21: 08042578942 | K21: Fidelity Bank | L21: 4 years | M21: Operation Manager | N21: 25 years | O21: Degree plus professional certificates | Q21: Large (Between $xx and $xx) | R21: Agree | S21: Agree | T21: Disagree | U21: Somewhat Agree | V21: Agree | W21: Somewhat Agree | X21: Strongly Agree | Y21: Somewhat Agree | Z21: Agree | AA21: Disagree | AC21: Strongly Disagree | AD21: Strongly Disagree | AE21: Somewhat Agree | AF21: Disagree | AG21: Strongly Disagree | AH21: Strongly Disagree | AI21: Strongly Disagree | AJ21: Strongly Disagree | AK21: Somewhat Disagree | AL21: Agree | AN21: StronglyAgree | AO21: StronglyDisagree | AP21: StronglyAgree | AQ21: Somewhat Agree | AR21: Neutral | AS21: Somewhat Agree | AT21: Somewhat Agree | AX21: Extremely High | AY21: Extremely High | BG21: 44
A22: 20 | B22: 28 | C22: Female | D22: Hispanic | E22: https://drive.google.com/file/d/1roQnN0MW-y5BZhuQMfpJQomf46UuC9kr/view?usp=drive_link | F22: Raphael Ogeth | G22: Banker / Teller | H22: ogethraphael@gmail.com | I22: Nil | J22: 07084110097 | K22: UBA | L22: 6 years | M22: Branch Manager | N22: 37 years | O22: HND holder | P22: 11 years | Q22: Large (Between $xx and $xx) | R22: Somewhat Agree | S22: Somewhat Agree | T22: Somewhat Disagree | U22: Somewhat Disagree | V22: Somewhat Agree | W22: Agree | X22: Somewhat Agree | Y22: Somewhat Agree | Z22: Somewhat Disagree | AA22: Somewhat Disagree | AB22: No | AC22: Disagree | AD22: Disagree | AE22: Somewhat Disagree | AF22: Disagree | AG22: Strongly Disagree | AH22: Somewhat Disagree | AI22: Somewhat Disagree | AJ22: Somewhat Disagree | AK22: Somewhat Disagree | AL22: Neutral | AM22: No | AN22: Agree | AO22: Somewhat Disagree | AP22: Somewhat Agree | AQ22: Agree | AR22: Somewhat Disagree | AS22: Somewhat Disagree | AT22: Neutral | AU22: 10 | AV22: 4 | AW22: 4 | AX22: Extremely High | AY22: Extremely High | AZ22: No | BB22: 4 | BD22: CEO | BE22: The largest sharaholders hes substantial voting right [for example above 35%) effectively controlling the company | BG22: 65
A23: 21 | B23: 31 | C23: Female | D23: Black | E23: https://drive.google.com/file/d/1e4I-czRHLLKrdhFqy9dcvdpbSnPIGUOD/view?usp=drive_link | F23: Adeokun Mohammed | G23: Banker | H23: kmohammed22@gmail.com | I23: 20 | J23: 08035229265 | K23: First Bank | L23: 16 years | M23: BM (Branch Manager) | N23: 45 years | O23: Degree plus professional certificates | P23: 15 years | Q23: Large (Between $xx and $xx) | R23: Agree | S23: Agree | T23: Somewhat Agree | U23: Somewhat Agree | V23: Agree | W23: Agree | X23: Strongly Agree | Y23: Strongly Agree | Z23: Somewhat Agree | AA23: Neutral | AB23: None | AC23: Strongly Disagree | AD23: Disagree | AE23: Disagree | AF23: Disagree | AG23: Strongly Disagree | AH23: Disagree | AI23: Somewhat Disagree | AJ23: Neutral | AK23: Somewhat Disagree | AL23: Somewhat Disagree | AM23: No | AN23: Agree | AO23: Somewhat Disagree | AP23: StronglyAgree | AQ23: Agree | AR23: Agree | AS23: Agree | AT23: Neutral | AU23: 3 | AV23: 3 | AW23: 3 | AX23: Extremely High | AY23: High | AZ23: No | BB23: 4 | BD23: CEO | BE23: The largest sharaholders hes substantial voting right [for example above 35%) effectively controlling the company | BF23: None | BG23: 61
A24: 22 | B24: 29 | C24: Female | D24: White | E24: https://drive.google.com/file/d/1SOv7-KxOC7S8TzWOt50zXggsK87MVp_B/view?usp=drive_link | F24: Emeje Doshing G. | G24: Security Guard | I24: 4 | J24: 08135423361 | K24: UBA | L24: 11 years | M24: Head of Operations | N24: 37 years | O24: Diploma level | P24: 11 years | Q24: Medium (Between $xx and $xx) | R24: Agree | S24: Neutral | T24: Disagree | U24: Agree | V24: Agree | W24: Strongly Agree | X24: Disagree | Y24: Agree | Z24: Disagree | AA24: Agree | AB24: No | AC24: Agree | AD24: Disagree | AE24: Agree | AF24: Disagree | AG24: Agree | AH24: Neutral | AI24: Disagree | AJ24: Agree | AK24: Disagree | AL24: Agree | AM24: No | AN24: Agree | AO24: Disagree | AP24: Agree | AQ24: Somewhat Disagree | AR24: Agree | AS24: Agree | AT24: Neutral | AU24: 6 | AV24: 3 | AW24: 3 | AX24: High | AY24: High | AZ24: Capacity | BC24: Manager | BD24: CEO | BE24: The largest sharaholders hes substantial voting right [for example above 35%) effectively controlling the company | BF24: No | BG24: 56
A25: 23 | B25: 26 | C25: Male | D25: White | E25: https://drive.google.com/file/d/16D5T662JtkJRuQej_2FG0MkyHUmm3Nil/view?usp=drive_link | F25: Shedrack Apeh | G25: Banker/Sales | H25: shedrackapeh4@gmail.com | I25: None | J25: 08098554734 | K25: Keystone Bank | L25: 4 years | M25: Manager | N25: 29 years | O25: HND holder | P25: 4 years | Q25: Large (Between $xx and $xx) | R25: Agree | S25: Strongly Agree | T25: Somewhat Agree | U25: Neutral | V25: Somewhat Agree | W25: Strongly Agree | X25: Strongly Agree | Y25: Agree | Z25: Strongly Disagree | AA25: Disagree | AB25: No | AC25: Strongly Disagree | AD25: Disagree | AE25: Disagree | AF25: Disagree | AG25: Strongly Disagree | AH25: Disagree | AI25: Neutral | AJ25: Somewhat Disagree | AK25: Disagree | AL25: Somewhat Disagree | AM25: No | AN25: StronglyAgree | AO25: Somewhat Disagree | AP25: Agree | AQ25: Somewhat Agree | AR25: Somewhat Agree | AS25: Neutral | AT25: Neutral | AU25: 8 | AV25: 4 | AW25: 4 | AX25: Extremely High | AY25: High | AZ25: No | BB25: 4 | BC25: Loans, Ethics, Audit, Council, Marketing | BD25: CEO | BE25: The largest sharaholders hes substantial voting right [for example above 35%) effectively controlling the company | BF25: No | BG25: 82
A26: 24 | B26: 28 | C26: Female | D26: White | E26: https://drive.google.com/file/d/1N7nEDlLpImApEgKDiJ21ZdpJah24wGAZ/view?usp=drive_link | F26: Ezeanuta Blessing | G26: Banker/Customer Care | H26: blessezeanuta@gmail.com | I26: None | J26: 08140408843 | K26: United Bank for Africa | L26: 6 years | M26: Head Sales | N26: 29 years | O26: Degree holder | Q26: Medium (Between $xx and $xx) | R26: Somewhat Agree | S26: Somewhat Agree | T26: Strongly Disagree | U26: Agree | V26: Agree | W26: Agree | X26: Agree | Y26: Somewhat Agree | Z26: Agree | AA26: Somewhat Agree | AC26: Disagree | AD26: Strongly Disagree | AE26: Disagree | AF26: Strongly Disagree | AG26: Strongly Disagree | AH26: Somewhat Disagree | AI26: Strongly Disagree | AJ26: Strongly Disagree | AL26: Agree | AN26: Agree | AO26: StronglyDisagree | AP26: Agree | AQ26: Agree | AR26: Somewhat Disagree | AS26: Somewhat Agree | AT26: Somewhat Agree | AX26: Extremely High | AY26: Extremely High | BG26: 44
A27: 25 | B27: 25 | C27: Male | D27: Black | E27: https://drive.google.com/file/d/1UL2EPuVuxeTj7Sj_NPi4UNlgPdW6RSek/view?usp=drive_link | F27: Ali Hussein | G27: Banker | H27: alihussein_2003@yahoo.com | I27: 25 | J27: 08100944610 | K27: Bank | L27: 8 years | M27: Bank Manager | N27: 45 years | O27: Degree holder | P27: 12 years | Q27: Large (Between $xx and $xx) | R27: Agree | S27: Somewhat Agree | T27: Somewhat Disagree | U27: Disagree | V27: Agree | W27: Agree | X27: Agree | Y27: Somewhat Agree | Z27: Disagree | AA27: Somewhat Disagree | AB27: No | AC27: Disagree | AD27: Somewhat Disagree | AE27: Disagree | AF27: Disagree | AG27: Somewhat Disagree | AH27: Somewhat Disagree | AI27: Disagree | AJ27: Somewhat Disagree | AK27: Disagree | AL27: Somewhat Disagree | AM27: No | AN27: Agree | AO27: Disagree | AP27: Agree | AQ27: Agree | AR27: Somewhat Disagree | AS27: Somewhat Agree | AT27: Neutral | AU27: 10 | AV27: 4 | AW27: 4 | AX27: Extremely High | AY27: Extremely High | BG27: 44
A28: 26 | B28: 29 | C28: Female | D28: White | E28: https://drive.google.com/file/d/1Pr3tg1A1Vf0L7mJIYNTlcnxzbXoe-h5M/view?usp=drive_link | F28: Oluwote Ogundipe | G28: Banking/CEO | I28: 5 | J28: 08100574582 | K28: UBA | L28: 4 years | M28: Branch Manager | N28: 38 years | O28: HND holder | P28: 10 years | Q28: Large (Between $xx and $xx) | R28: Strongly Agree | S28: Agree | T28: Disagree | U28: Somewhat Disagree | V28: Strongly Agree | W28: Strongly Agree | X28: Somewhat Agree | Y28: Somewhat Agree | Z28: Disagree | AA28: Neutral | AB28: No | AC28: Somewhat Disagree | AD28: Strongly Disagree | AE28: Disagree | AF28: Disagree | AG28: Disagree | AH28: Strongly Disagree | AI28: Somewhat Disagree | AJ28: Disagree | AK28: Somewhat Disagree | AL28: Somewhat Disagree | AM28: No | AN28: StronglyAgree | AO28: StronglyDisagree | AP28: StronglyAgree | AQ28: Agree | AR28: Disagree | AS28: Neutral | AT28: Neutral | AU28: 10 | AV28: 4 | AW28: 4 | AX28: Extremely High | AY28: Extremely High | AZ28: No | BB28: 4 | BC28: Tony Elumelu | BD28: CEO | BE28: The largest sharaholders hes substantial voting right [for example above 35%) effectively controlling the company | BF28: No | BG28: 57
A29: 27 | B29: 45 | C29: Male | D29: White | E29: https://drive.google.com/file/d/1M6Uv3ouknR-csnt1D_R44ImykCWXMcX3/view?usp=drive_link | F29: Ali Hussein | G29: Banker | H29: alihussein_2003@yahoo.com | I29: 25 | J29: 08100944610 | K29: Bank | L29: 8 years | M29: Branch Manager | N29: 45 years | O29: Degree holder | P29: 12 years | Q29: Large (Between $xx and $xx) | R29: Agree | S29: Agree | T29: Somewhat Agree | U29: Somewhat Disagree | V29: Agree | W29: Agree | X29: Agree | Y29: Somewhat Disagree | Z29: Disagree | AA29: Somewhat Disagree | AB29: No | AC29: Disagree | AD29: Disagree | AE29: Somewhat Disagree | AF29: Disagree | AG29: Somewhat Disagree | AH29: Somewhat Disagree | AI29: Somewhat Disagree | AJ29: Disagree | AK29: Somewhat Disagree | AL29: Disagree | AM29: No | AN29: Agree | AO29: Disagree | AP29: Agree | AQ29: Agree | AR29: Neutral | AS29: Neutral | AT29: Neutral | AU29: 10 | AV29: 4 | AW29: 4 | AX29: Extremely High | AY29: Extremely High | AZ29: No | BB29: 4 | BC29: Tony Elumelu | BD29: CEO | BE29: The largest sharaholders hes substantial voting right [for example above 35%) effectively controlling the company | BF29: No | BG29: 57
A30: 28 | B30: 49 | C30: Male | D30: White | E30: https://drive.google.com/file/d/17EdD2baxpPaxa6wESyGNIn9nueNxxr9E/view?usp=drive_link | G30: Banker/Cashier | I30: None | K30: Wema Bank | L30: 5 years | M30: Supervisor | N30: 28 years | O30: HND holder | P30: 5 years | Q30: Large (Between $xx and $xx) | R30: Agree | S30: Somewhat Agree | T30: Disagree | U30: Somewhat Disagree | V30: Agree | W30: Strongly Agree | X30: Agree | Y30: Neutral | Z30: Disagree | AA30: Somewhat Disagree | AC30: Strongly Disagree | AD30: Disagree | AE30: Somewhat Agree | AF30: Disagree | AG30: Disagree | AH30: Disagree | AI30: Somewhat Disagree | AJ30: Somewhat Disagree | AK30: Somewhat Disagree | AL30: Disagree | AM30: No | AN30: StronglyAgree | AO30: Somewhat Disagree | AP30: Agree | AQ30: Somewhat Agree | AR30: Somewhat Disagree | AS30: Neutral | AT30: Neutral | AU30: 13 | AV30: 6 | AW30: 7 | AX30: Extremely High | AY30: High | AZ30: No | BB30: 7 | BC30: Dr. Alayemi Si, Moruf Oseni, Wole Famuyibo, Isiyaka S. Kung, Yusuf Kaura | BD30: CEO | BE30: The largest sharaholders hes substantial voting right [for example above 35%) effectively controlling the company | BF30: No | BG30: 64
A31: 29 | B31: 25 | C31: Male | D31: White | E31: https://drive.google.com/file/d/1nN_bboikhZ897AMas0fWNmaMIdNDN6jG/view?usp=drive_link | F31: Ibrahim Sadiq | G31: Banking | H31: sadiqibrahimabumi@gmail.com | J31: 08064518330 | K31: Keystone Bank Ltd | L31: 4 years | M31: Branch Manager | O31: Masters holder | P31: 4 years | Q31: Large (Between $xx and $xx) | R31: Agree | S31: Agree | T31: Neutral | U31: Neutral | V31: Agree | W31: Agree | X31: Agree | Y31: Agree | Z31: Disagree | AA31: Neutral | AB31: None | AC31: Disagree | AD31: Strongly Disagree | AE31: Disagree | AF31: Strongly Disagree | AG31: Strongly Disagree | AH31: Disagree | AI31: Disagree | AJ31: Strongly Disagree | AK31: Neutral | AL31: Disagree | AM31: None | AN31: StronglyAgree | AO31: Agree | AP31: Agree | AQ31: Agree | AR31: Neutral | AS31: Somewhat Agree | AT31: Disagree | AU31: 3 | AV31: 3 | AX31: High | AY31: High | AZ31: No | BB31: 1 | BD31: CEO | BE31: The largest sharaholders hes substantial voting right [for example above 35%) effectively controlling the company | BG31: 77
A32: 30 | B32: 47 | C32: Male | D32: White | E32: https://drive.google.com/file/d/1sF7gtxO-VUok_zZKU7QQOnNW5YsORRjM/view?usp=drive_link | G32: Banker | I32: None | K32: Zenith Bank | L32: 3 years | M32: Supervisor | N32: 26 years | O32: HND holder | P32: 3 years | Q32: Large (Between $xx and $xx) | R32: Strongly Agree | S32: Somewhat Agree | T32: Somewhat Disagree | U32: Disagree | V32: Agree | W32: Strongly Agree | X32: Agree | Y32: Somewhat Agree | Z32: Disagree | AA32: Somewhat Disagree | AB32: No | AC32: Strongly Disagree | AD32: Strongly Disagree | AE32: Disagree | AF32: Disagree | AG32: Strongly Disagree | AH32: Disagree | AI32: Disagree | AJ32: Disagree | AK32: Disagree | AL32: Somewhat Disagree | AM32: No | AN32: StronglyAgree | AO32: Disagree | AP32: StronglyAgree | AQ32: Somewhat Agree | AR32: Neutral | AS32: Neutral | AT32: Neutral | AU32: 12 | AV32: 4 | AW32: 8 | AX32: Extremely High | AY32: Extremely High | AZ32: No | BB32: 4 | BC32: Jim Ovia, Adozi Nwapa, Mustafa Bello, Adaora Umeji. | BD32: CEO | BE32: The largest sharaholders hes substantial voting right [for example above 35%) effectively controlling the company | BF32: No | BG32: 39
A33: 31 | B33: 44 | C33: Female | D33: White | E33: https://drive.google.com/file/d/1kGV66NOqE0xz3b5Qs290rTuhGmqdc7Us/view?usp=drive_link | F33: Barnabas Bonduamba | G33: Banker/Teller | H33: bonduas@gmail.com | I33: None | J33: 08031852182 | K33: United Bank for Africa | L33: 8 years | M33: Head Cashier | N33: 35 years | O33: Masters holder | P33: 10 years | Q33: Large (Between $xx and $xx) | R33: Agree | S33: Somewhat Agree | T33: Somewhat Disagree | U33: Somewhat Disagree | V33: Agree | W33: Strongly Agree | X33: Agree | Y33: Somewhat Agree | Z33: Somewhat Disagree | AA33: Somewhat Disagree | AB33: No | AC33: Somewhat Disagree | AD33: Disagree | AE33: Somewhat Disagree | AF33: Disagree | AG33: Strongly Disagree | AH33: Somewhat Disagree | AI33: Somewhat Disagree | AJ33: Somewhat Disagree | AK33: Somewhat Disagree | AL33: Disagree | AM33: No | AN33: Agree | AO33: Somewhat Disagree | AP33: Somewhat Agree | AQ33: Somewhat Agree | AR33: Somewhat Disagree | AS33: Somewhat Agree | AT33: Neutral | AU33: 8 | AV33: 2 | AW33: 4 | AX33: Extremely High | AY33: Extremely High | AZ33: No | BB33: 2 | BC33: Tony Elumelu | BD33: CEO | BE33: The largest sharaholders hes substantial voting right [for example above 35%) effectively controlling the company | BG33: 54
A34: 32 | B34: 47 | C34: Female | D34: White | E34: https://drive.google.com/file/d/1Lj7ADICgP83l0RVzrh40lKBuMYgeZ2mf/view?usp=drive_link | F34: Jarad Godwin | H34: godwinjarad@gmail.com | I34: None | J34: 07068474653 | K34: Wema Bank | L34: 8 years | M34: Head of Operations | N34: 36 years | O34: Degree holder | P34: 10 years | Q34: Large (Between $xx and $xx) | R34: Disagree | S34: StronglyDisagree | T34: StronglyDisagree | U34: Disagree | V34: StronglyDisagree | W34: Somewhat Disagree | X34: Somewhat Agree | Y34: Strongly Disagree | Z34: Agree | AA34: Strongly Agree | AC34: Somewhat Agree | AD34: Somewhat Agree | AE34: Strongly Agree | AF34: Agree | AG34: Somewhat Agree | AH34: Strongly Agree | AI34: Strongly Agree | AJ34: Agree | AK34: Agree | AL34: Strongly Disagree | AU34: 6 | AV34: 5 | AW34: 5 | AX34: Extremely Low | AY34: Low | BG34: 67
A35: 33 | B35: 24 | C35: Female | D35: White | E35: https://drive.google.com/file/d/1i0_EdzTY3jWrELUByvsTnTaVbvjYaDg3/view?usp=drive_link | F35: Elizabeth Michael | G35: Banking/Customer Care | H35: elizabeth12@gmail.com | I35: Nil | J35: 09095077027 | K35: First Bank | L35: 4 years | M35: Operation Manager | N35: 26 years | O35: Diploma level | P35: 4 years | Q35: Large (Between $xx and $xx) | R35: Strongly Agree | S35: Agree | T35: Somewhat Disagree | U35: Somewhat Disagree | V35: Strongly Agree | W35: Strongly Agree | X35: Strongly Agree | Y35: Agree | Z35: Somewhat Disagree | AA35: Somewhat Disagree | AB35: No | AC35: Strongly Disagree | AD35: Disagree | AE35: Somewhat Disagree | AF35: Disagree | AG35: Strongly Disagree | AH35: Somewhat Disagree | AI35: Somewhat Disagree | AJ35: Disagree | AK35: Somewhat Disagree | AL35: Somewhat Disagree | AM35: No | AN35: StronglyAgree | AO35: Strongly Disagree | AP35: Agree | AQ35: Agree | AR35: Somewhat Disagree | AS35: Somewhat Disagree | AT35: Neutral | AU35: 10 | AV35: 4 | AW35: 4 | AX35: High | AY35: Extremely High | AZ35: No | BB35: 4 | BC35: Oluwasegun Hubosa, Patricia lyamabo. | BD35: CEO | BE35: The largest sharaholders hes substantial voting right [for example above 35%) effectively controlling the company | BF35: No | BG35: 68
A36: 34 | B36: 29 | C36: Female | D36: White | E36: https://drive.google.com/file/d/1ShI83uetTiixKtFp2T4zGfJ3Nbayz7CW/view?usp=drive_link | G36: Banker | K36: Wema Bank | L36: 5 years | M36: Business Team Leader | O36: Degree holder | Q36: Large (Between $xx and $xx) | R36: Somewhat Agree | S36: Agree | T36: Agree | U36: Somewhat Agree | V36: Agree | W36: Agree | X36: Agree | Y36: Disagree | Z36: Disagree | AA36: Somewhat Disagree | AC36: Disagree | AD36: Disagree | AE36: Somewhat Disagree | AF36: Somewhat Disagree | AG36: Disagree | AH36: Somewhat Agree | AI36: Disagree | AJ36: Disagree | AK36: Somewhat Agree | AL36: Somewhat Disagree | AN36: Strongly Agree | AO36: Disagree | AP36: Agree | AQ36: Agree | AR36: Neutral | AS36: Disagree | AT36: Disagree | AU36: 10 | AV36: 5 | AW36: 7 | AX36: Extremely High | AY36: High | AZ36: No | BB36: 4 | BD36: Board | BF36: No | BG36: 64
A37: 35 | B37: 33 | C37: Female | D37: White | E37: https://drive.google.com/file/d/1MZSppHiQp6jKD66yH8i1bagngpGe8QOl/view?usp=drive_link | G37: Banker / Customer Care | I37: None | K37: UBA | L37: 4 years | M37: Supervisor | N37: 26 years | O37: Degree holder | P37: 4 years | Q37: Large (Between $xx and $xx) | R37: Strongly Agree | S37: Somewhat Agree | T37: Somewhat Disagree | U37: Disagree | V37: Strongly Agree | W37: Strongly Agree | X37: Agree | Y37: Somewhat Disagree | Z37: Somewhat Disagree | AA37: Somewhat Disagree | AB37: No | AC37: Strongly Disagree | AD37: Disagree | AE37: Strongly Disagree | AF37: Somewhat Disagree | AG37: Strongly Disagree | AH37: Somewhat Disagree | AI37: Somewhat Disagree | AJ37: Disagree | AK37: Somewhat Disagree | AL37: Somewhat Disagree | AM37: No | AN37: Strongly Agree | AO37: Somewhat Disagree | AP37: Strongly Agree | AQ37: Agree | AR37: Neutral | AS37: Neutral | AT37: Neutral | AU37: 4 | AV37: 4 | AW37: 4 | AX37: Extremely High | AY37: High | AZ37: No | BB37: 4 | BC37: Anthony Stanley, Oliver Alawuba, Alex Afolabi, Muyiwa Akinyemi, Manafatu Asola. | BD37: CEO | BE37: The largest sharaholders hes substantial voting right [for example above 35%) effectively controlling the company | BG37: 58
A38: 36 | B38: 38 | C38: Female | D38: White | E38: https://drive.google.com/file/d/1ZE1HpHcGWofufsL0QXip3lKhnEew-X-t/view?usp=drive_link | G38: Banking | I38: 6 | K38: Keystone Bank Ltd | L38: 5 years | M38: Manager | N38: 33 years | O38: Degree holder, Masters holder plus professional certificates | Q38: Medium (Between $xx and $xx) | R38: Somewhat Agree | S38: Agree | T38: Disagree | U38: Agree | V38: Strongly Agree | W38: Strongly Agree | X38: Strongly Agree | Y38: Somewhat Agree | Z38: Somewhat Agree | AA38: Disagree | AC38: Strongly Disagree | AD38: Strongly Disagree | AE38: Disagree | AF38: Strongly Disagree | AG38: Strongly Disagree | AH38: Disagree | AI38: Strongly Disagree | AJ38: Strongly Disagree | AK38: Disagree | AL38: Somewhat Agree | AN38: Strongly Agree | AO38: Disagree | AP38: Agree | AQ38: Somewhat Agree | AR38: Disagree | AS38: Somewhat Agree | AT38: Somewhat Agree | AX38: Extremely High | AY38: High | BG38: 46
A39: 37 | B39: 52 | C39: Female | D39: Black | E39: https://drive.google.com/file/d/15i9RZZ2-Mmo8TUwWDyKqDXzvi2O42au_/view?usp=drive_link | F39: Oche Emmanuel | G39: euumqiweloche22@gmail.com | H39: Bawis Audtor | I39: i | J39: 08032477994 | K39: huy Stone Banp | L39: 7 Years | M39: Heas of operation | N39: 34 Years | O39: Degree holder | P39: 10 years | Q39: Large (Between $xx and $xx) | R39: Agree | S39: Somewhat Agree | T39: Somewhat Disagree | U39: Somewhat Disagree | V39: Strongly Agree | W39: Strongly Agree | X39: Agree | Y39: Agree | Z39: Somewhat Disagree | AA39: Somewhat Disagree | AB39: No | AC39: Disagree | AD39: Somewhat disagree | AE39: Disagree | AF39: Disagree | AG39: Strongly Disagree | AH39: Somewhat disagree | AI39: Somewhat disagree | AJ39: Somewhat disagree | AK39: Disagree | AL39: Somewhat disagree | AM39: No | AN39: Somewhat disagree | AO39: Disagree | AP39: Somewhat disagree | AQ39: Somewhat Agree | AR39: Somewhat Disagree | AS39: Somewhat Disagree | AT39: Disagree | AU39: 10 | AV39: 4 | AW39: 4 | AX39: Extremely High | AY39: Extremely High | BD39: CEO | BE39: The largest sharaholders hes substantial voting right [for example above 35%) effectively controlling the company | BG39: 46
A40: 38 | B40: 32 | C40: Male | D40: Black | E40: https://drive.google.com/file/d/1i3rrZqDHPZ0sSWnshd7MoSZyWf1s7z5a/view?usp=drive_link | F40: Laraba Peul | G40: Banang Sales Rep | H40: larabapulsuoy123@gmail.com | I40: 8 | J40: 08068657512 | K40: GT PauR | L40: 12 Years | M40: Regualac manager | N40: 41 Years | O40: Masters holder | P40: 15 years | Q40: Large (Between $xx and $xx) | R40: Strongly Agree | S40: Somewhat Agree | T40: Somewhat Disagree | U40: Somewhat Disagree | V40: Agree | W40: Strongly Agree | X40: Somewhat Agree | Y40: Somewhat Agree | Z40: Disagree | AA40: Somewhat Disagree | AC40: Disagree | AD40: Disagree | AE40: Disagree | AF40: Strongly Disagree | AG40: Somewhat Disagree | AH40: Somewhat Disagree | AI40: Disagree | AJ40: Somewhat Disagree | AK40: Disagree | AL40: Somewhat Disagree | AM40: No | AN40: Strongly Disagree | AO40: Disagree | AP40: Agree | AQ40: Agree | AR40: Neutral | AS40: Neutral | AT40: Somewhat Disagree | AX40: High | AY40: Extremely High | AZ40: No | BD40: CEO | BE40: The largest sharaholders hes substantial voting right [for example above 35%) effectively controlling the company | BG40: 38
...

Sheet ID2

Sheet Key ID2
A3: Name | C3: Respondent ID
A4: role | C4: Respondent Role
A5: email | C5: Respondent Email
A6: reporttoyou | C6: How many people does the respondant report to?
A7: teleohoneNum | C7: Responant telephone Number
A8: organisation | C8: Name of Organisation
A9: yearsinorg | C9: How long have you been in your organisation?
A10: WhoyUReport | C10: Who do you report to?
A11: ageinorg | C11: Respondent age
A12: eduQualifi
A13: yearinFin
A14: Bank Size | C14: Respondent age
A15: sex | C15: Respondent sex
A16: race | C16: Respondent race
A17: BME | C17: Respondent BME Status, 1= BME, 0= non BME
A18: Educ | C18: Respondent Education level, 1 = graduate degree, 0=no graduate degree
A19: Questions | B19: Latent Variable | C19: Twenty Questions on derpression expressed when learning statistics | D19: StronglyDisagree | E19: Disagree | F19: Neutral | G19: Agree | H19: StronglyAgree
D20: 1 | E20: 2 | F20: 3 | G20: 4 | H20: 5
A21: qu1 | B21: Affective | C21: Statistics makes you feel sad
A22: qu2 | C22: Statistics makes you feel pessimistic about the future
A23: qu3 | C23: Statistics makes you feel like a failure
A24: qu4 | C24: Statistics makes you feel dissatisfied
A25: qu5 | C25: Statistics makes you feel guilty or unworthy
A26: qu6 | C26: Statistics makes you feel that I am being punished
A27: qu7 | C27: Statistics makes you feel disappointed in myself
A28: qu8 | C28: Statistics makes you feel am very critical of myself
A29: qu9 | C29: Statistics makes you feel like harming myself
A30: qu10 | C30: Statistics makes you feel crying more than usual
A31: qu11 | B31: Physical | C31: Statistics makes you become annoyed or irritated easily
A32: qu12 | C32: Statistics makes you have lost interest in other people
A33: qu13 | C33: Statistics makes you have trouble making decision
A34: qu14 | C34: Statistics makes you feel unattractive
A35: qu15 | C35: Statistics makes you feel like not working
A36: qu16 | C36: Statistics makes you have trouble sleeping
A37: qu17 | C37: Statistics makes you feel tired or fatigue
A38: qu18 | C38: Statistics makes my appetite lower than usual
A39: qu19 | C39: Statistics makes you concerned about your health
A40: qu20 | C40: Statistics makes you experience decrease in libido
A41: TotalScore

Sheet Copy of Data
E1: Name | F1: Role | G1: Email address
A2: id | B2: age | C2: sex | D2: race | E2: qu1 | F2: qu2 | G2: qu3 | H2: qu4 | I2: qu5 | J2: qu6 | K2: qu7 | L2: qu8 | M2: qu9 | N2: qu10 | O2: qu11 | P2: qu12 | Q2: qu13 | R2: qu14 | S2: qu15 | T2: qu16 | U2: qu17 | V2: qu18 | W2: qu19 | X2: qu20 | Y2: TotalScore
A3: 1 | B3: 49 | C3: Male | D3: White | F3: Banker | G3: Neutral | H3: Neutral | I3: Neutral | J3: Neutral | K3: Neutral | L3: Neutral | M3: Neutral | N3: Disagree | O3: Neutral | P3: Neutral | Q3: Neutral | R3: Disagree | S3: Disagree | T3: Neutral | U3: Neutral | V3: Disagree | W3: Neutral | X3: StronglyDisagree | Y3: 54
A4: 2 | B4: 52 | C4: Female | D4: White | E4: Neutral | F4: Disagree | G4: Neutral | H4: Neutral | I4: Disagree | J4: Disagree | K4: Disagree | L4: Neutral | M4: Neutral | N4: Neutral | O4: Neutral | P4: Neutral | Q4: Neutral | R4: Neutral | S4: Neutral | T4: Neutral | U4: Neutral | V4: Neutral | W4: Neutral | X4: Disagree | Y4: 55
A5: 3 | B5: 31 | C5: Male | D5: Hispanic | E5: Neutral | F5: Disagree | G5: Disagree | H5: Neutral | I5: Disagree | J5: Disagree | K5: Neutral | L5: Disagree | M5: Neutral | N5: Disagree | O5: Agree | P5: Agree | Q5: Neutral | R5: Agree | S5: Neutral | T5: Neutral | U5: Neutral | V5: Agree | W5: Agree | X5: Disagree | Y5: 58
A6: 4 | B6: 28 | C6: Male | D6: Black | E6: Agree | F6: Neutral | G6: Neutral | H6: Neutral | I6: Neutral | J6: Disagree | K6: Neutral | L6: Neutral | M6: Neutral | N6: Neutral | O6: Neutral | P6: Neutral | Q6: Agree | R6: Neutral | S6: Neutral | T6: Neutral | U6: Agree | V6: Neutral | W6: Neutral | X6: Neutral | Y6: 62
A7: 5 | B7: 29 | C7: Male | D7: White | E7: Agree | F7: Disagree | G7: Agree | H7: Agree | I7: Neutral | J7: Agree | K7: Agree | L7: Agree | M7: Agree | N7: Agree | O7: Neutral | P7: Neutral | Q7: Neutral | R7: StronglyDisagree | S7: Disagree | T7: Neutral | U7: Neutral | V7: Neutral | W7: Neutral | X7: StronglyDisagree | Y7: 62
A8: 6 | B8: 50 | C8: Female | D8: Black | E8: Neutral | F8: Disagree | G8: Neutral | H8: Disagree | I8: Disagree | J8: Disagree | K8: Neutral | L8: Neutral | M8: Disagree | N8: Neutral | O8: Neutral | P8: Neutral | Q8: Neutral | R8: Disagree | S8: Neutral | T8: Neutral | U8: Neutral | V8: Neutral | W8: Neutral | X8: Neutral | Y8: 54
A9: 7 | B9: 31 | C9: Female | D9: White | E9: Disagree | F9: StronglyDisagree | G9: Disagree | H9: Disagree | I9: Disagree | J9: Disagree | K9: Disagree | L9: StronglyDisagree | M9: Disagree | N9: Disagree | O9: Neutral | P9: Agree | Q9: Neutral | R9: Disagree | S9: Neutral | T9: Agree | U9: Neutral | V9: Neutral | W9: Neutral | X9: Neutral | Y9: 49
A10: 8 | B10: 24 | C10: Female | D10: Black | E10: Neutral | F10: Neutral | G10: Neutral | H10: Neutral | I10: Neutral | J10: Agree | K10: Neutral | L10: Neutral | M10: Neutral | N10: Agree | O10: Agree | P10: Neutral | Q10: Neutral | R10: Neutral | S10: Neutral | T10: Neutral | U10: Agree | V10: Neutral | W10: Agree | X10: Disagree | Y10: 64
A11: 9 | B11: 32 | C11: Female | D11: Black | E11: Agree | F11: Agree | G11: Agree | H11: Agree | I11: Neutral | J11: Agree | K11: Neutral | L11: Neutral | M11: Neutral | N11: Agree | O11: Neutral | P11: Neutral | Q11: Agree | R11: Disagree | S11: Neutral | T11: Neutral | U11: Neutral | V11: Neutral | W11: Agree | X11: Disagree | Y11: 66
A12: 10 | B12: 33 | C12: Female | D12: White | E12: Neutral | F12: Agree | G12: Agree | H12: Agree | I12: Agree | J12: Agree | K12: Agree | L12: Agree | M12: Agree | N12: Agree | O12: Disagree | P12: Disagree | Q12: Neutral | R12: StronglyDisagree | S12: Disagree | T12: Disagree | U12: Disagree | V12: Disagree | W12: Neutral | X12: StronglyDisagree | Y12: 59
A13: 11 | B13: 46 | C13: Female | D13: White | E13: Neutral | F13: Neutral | G13: Agree | H13: Neutral | I13: Neutral | J13: Neutral | K13: Agree | L13: Neutral | M13: Neutral | N13: Agree | O13: Disagree | P13: Neutral | Q13: Neutral | R13: Disagree | S13: Neutral | T13: Neutral | U13: Neutral | V13: Neutral | W13: Neutral | X13: StronglyDisagree | Y13: 59
A14: 12 | B14: 39 | C14: Female | D14: White | E14: StronglyAgree | F14: Agree | G14: StronglyAgree | H14: Agree | I14: StronglyAgree | J14: Agree | K14: Agree | L14: StronglyAgree | M14: StronglyAgree | N14: StronglyAgree | O14: Agree | P14: StronglyAgree | Q14: Agree | R14: Neutral | S14: Agree | T14: Agree | U14: Agree | V14: Agree | W14: Neutral | X14: Neutral | Y14: 84
A15: 13 | B15: 46 | C15: Male | D15: Black | E15: Neutral | F15: Neutral | G15: Neutral | H15: Neutral | I15: Neutral | J15: Agree | K15: Agree | L15: Neutral | M15: Neutral | N15: Neutral | O15: Neutral | P15: Neutral | Q15: Neutral | R15: Disagree | S15: Neutral | T15: Neutral | U15: Disagree | V15: Neutral | W15: Disagree | X15: Disagree | Y15: 58
... A1002: 1000 | B1002: 30 | C1002: Female | D1002: Black | E1002: Agree | F1002: Neutral | G1002: Agree | H1002: Agree | I1002: Agree | J1002: Agree | K1002: Agree | L1002: StronglyAgree | M1002: Agree | N1002: Agree | O1002: Agree | P1002: StronglyAgree | Q1002: StronglyAgree | R1002: Agree | S1002: StronglyAgree | T1002: StronglyAgree | U1002: StronglyAgree | V1002: StronglyAgree | W1002: StronglyAgree | X1002: Agree | Y1002: 87

Sheet Data 1
A1: StronglyDisagree | B1: id | C1: age | D1: sex | E1: race | F1: qu1 | G1: qu2 | H1: qu3 | I1: qu4 | J1: qu5 | K1: qu6 | L1: qu7 | M1: qu8 | N1: qu9 | O1: qu10 | P1: qu11 | Q1: qu12 | R1: qu13 | S1: qu14 | T1: qu15 | U1: qu16 | V1: qu17 | W1: qu18 | X1: qu19 | Y1: qu20 | Z1: TotalScore
A2: Disagree | B2: 1 | C2: 49 | D2: Male | E2: White | F2: =MATCH(Data!F3,$A$1:$A$5,0) -> #N/A | G2: =MATCH(Data!G3,$A$1:$A$5,0) -> #N/A | H2: =MATCH(Data!H3,$A$1:$A$5,0) -> #N/A | I2: =MATCH(Data!I3,$A$1:$A$5,0) -> #N/A | J2: =MATCH(Data!J3,$A$1:$A$5,0) -> #N/A | K2: =MATCH(Data!K3,$A$1:$A$5,0) -> #N/A | L2: =MATCH(Data!L3,$A$1:$A$5,0) -> #N/A | M2: =MATCH(Data!M3,$A$1:$A$5,0) -> #N/A | ... Y2: =MATCH(Data!Y3,$A$1:$A$5,0) -> 4 | Z2: =SUM(F2:Y2) -> #N/A
A3: Neutral | B3: 2 | C3: 52 | D3: Female | E3: White | F3: =MATCH(Data!F4,$A$1:$A$5,0) -> #N/A | G3: =MATCH(Data!G4,$A$1:$A$5,0) -> #N/A | H3: =MATCH(Data!H4,$A$1:$A$5,0) -> #N/A | I3: =MATCH(Data!I4,$A$1:$A$5,0) -> #N/A | J3: =MATCH(Data!J4,$A$1:$A$5,0) -> #N/A | K3: =MATCH(Data!K4,$A$1:$A$5,0) -> #N/A | L3: =MATCH(Data!L4,$A$1:$A$5,0) -> #N/A | M3: =MATCH(Data!M4,$A$1:$A$5,0) -> #N/A | ... Y3: =MATCH(Data!Y4,$A$1:$A$5,0) -> #N/A | Z3: =SUM(F3:Y3) -> #N/A
A4: Agree | B4: 3 | C4: 31 | D4: Male | E4: Hispanic | F4: =MATCH(Data!F5,$A$1:$A$5,0) -> #N/A | G4: =MATCH(Data!G5,$A$1:$A$5,0) -> #N/A | H4: =MATCH(Data!H5,$A$1:$A$5,0) -> #N/A | I4: =MATCH(Data!I5,$A$1:$A$5,0) -> #N/A | J4: =MATCH(Data!J5,$A$1:$A$5,0) -> #N/A | K4: =MATCH(Data!K5,$A$1:$A$5,0) -> #N/A | L4: =MATCH(Data!L5,$A$1:$A$5,0) -> #N/A | M4: =MATCH(Data!M5,$A$1:$A$5,0) -> #N/A | ... Y4: =MATCH(Data!Y5,$A$1:$A$5,0) -> #N/A | Z4: =SUM(F4:Y4) -> #N/A
A5: StronglyAgree | B5: 4 | C5: 28 | D5: Male | E5: Black | F5: =MATCH(Data!F6,$A$1:$A$5,0) -> #N/A | G5: =MATCH(Data!G6,$A$1:$A$5,0) -> #N/A | H5: =MATCH(Data!H6,$A$1:$A$5,0) -> #N/A | I5: =MATCH(Data!I6,$A$1:$A$5,0) -> #N/A | J5: =MATCH(Data!J6,$A$1:$A$5,0) -> #N/A | K5: =MATCH(Data!K6,$A$1:$A$5,0) -> #N/A | L5: =MATCH(Data!L6,$A$1:$A$5,0) -> #N/A | M5: =MATCH(Data!M6,$A$1:$A$5,0) -> #N/A | ... Y5: =MATCH(Data!Y6,$A$1:$A$5,0) -> #N/A | Z5: =SUM(F5:Y5) -> #N/A
B6: 5 | C6: 29 | D6: Male | E6: White | F6: =MATCH(Data!F7,$A$1:$A$5,0) -> #N/A | G6: =MATCH(Data!G7,$A$1:$A$5,0) -> #N/A | H6: =MATCH(Data!H7,$A$1:$A$5,0) -> #N/A | I6: =MATCH(Data!I7,$A$1:$A$5,0) -> #N/A | J6: =MATCH(Data!J7,$A$1:$A$5,0) -> #N/A | K6: =MATCH(Data!K7,$A$1:$A$5,0) -> #N/A | L6: =MATCH(Data!L7,$A$1:$A$5,0) -> #N/A | M6: =MATCH(Data!M7,$A$1:$A$5,0) -> #N/A | ... Y6: =MATCH(Data!Y7,$A$1:$A$5,0) -> #N/A | Z6: =SUM(F6:Y6) -> #N/A
B7: 6 | C7: 50 | D7: Female | E7: Black | F7: =MATCH(Data!F8,$A$1:$A$5,0) -> #N/A | G7: =MATCH(Data!G8,$A$1:$A$5,0) -> #N/A | H7: =MATCH(Data!H8,$A$1:$A$5,0) -> #N/A | I7: =MATCH(Data!I8,$A$1:$A$5,0) -> #N/A | J7: =MATCH(Data!J8,$A$1:$A$5,0) -> #N/A | K7: =MATCH(Data!K8,$A$1:$A$5,0) -> #N/A | L7: =MATCH(Data!L8,$A$1:$A$5,0) -> #N/A | M7: =MATCH(Data!M8,$A$1:$A$5,0) -> #N/A | ... Y7: =MATCH(Data!Y8,$A$1:$A$5,0) -> 3 | Z7: =SUM(F7:Y7) -> #N/A
B8: 7 | C8: 31 | D8: Female | E8: White | F8: =MATCH(Data!F9,$A$1:$A$5,0) -> #N/A | G8: =MATCH(Data!G9,$A$1:$A$5,0) -> #N/A | H8: =MATCH(Data!H9,$A$1:$A$5,0) -> #N/A | I8: =MATCH(Data!I9,$A$1:$A$5,0) -> #N/A | J8: =MATCH(Data!J9,$A$1:$A$5,0) -> #N/A | K8: =MATCH(Data!K9,$A$1:$A$5,0) -> #N/A | L8: =MATCH(Data!L9,$A$1:$A$5,0) -> #N/A | M8: =MATCH(Data!M9,$A$1:$A$5,0) -> #N/A | ... Y8: =MATCH(Data!Y9,$A$1:$A$5,0) -> #N/A | Z8: =SUM(F8:Y8) -> #N/A
B9: 8 | C9: 24 | D9: Female | E9: Black | F9: =MATCH(Data!F10,$A$1:$A$5,0) -> #N/A | G9: =MATCH(Data!G10,$A$1:$A$5,0) -> #N/A | H9: =MATCH(Data!H10,$A$1:$A$5,0) -> #N/A | I9: =MATCH(Data!I10,$A$1:$A$5,0) -> #N/A | J9: =MATCH(Data!J10,$A$1:$A$5,0) -> #N/A | K9: =MATCH(Data!K10,$A$1:$A$5,0) -> #N/A | L9: =MATCH(Data!L10,$A$1:$A$5,0) -> #N/A | M9: =MATCH(Data!M10,$A$1:$A$5,0) -> #N/A | ... Y9: =MATCH(Data!Y10,$A$1:$A$5,0) -> #N/A | Z9: =SUM(F9:Y9) -> #N/A
B10: 9 | C10: 32 | D10: Female | E10: Black | F10: =MATCH(Data!F11,$A$1:$A$5,0) -> #N/A | G10: =MATCH(Data!G11,$A$1:$A$5,0) -> #N/A | H10: =MATCH(Data!H11,$A$1:$A$5,0) -> #N/A | I10: =MATCH(Data!I11,$A$1:$A$5,0) -> #N/A | J10: =MATCH(#REF!,$A$1:$A$5,0) -> #REF! | K10: =MATCH(Data!K11,$A$1:$A$5,0) -> #N/A | L10: =MATCH(Data!L11,$A$1:$A$5,0) -> #N/A | M10: =MATCH(Data!M11,$A$1:$A$5,0) -> #N/A | N10: =MATCH(Data!N11,$A$1:$A$5,0) -> #N/A | O10: =MATCH(Data!O11,$A$1:$A$5,0) -> #N/A | P10: =MATCH(Data!P11,$A$1:$A$5,0) -> #N/A | Q10: =MATCH(Data!Q11,$A$1:$A$5,0) -> #N/A | R10: =MATCH(Data!R11,$A$1:$A$5,0) -> 4 | ... Y10: =MATCH(Data!Y11,$A$1:$A$5,0) -> 4 | Z10: =SUM(F10:Y10) -> #N/A
B11: 10 | C11: 33 | D11: Female | E11: White | F11: =MATCH(Data!F12,$A$1:$A$5,0) -> #N/A | G11: =MATCH(Data!G12,$A$1:$A$5,0) -> #N/A | H11: =MATCH(Data!H12,$A$1:$A$5,0) -> #N/A | I11: =MATCH(Data!I12,$A$1:$A$5,0) -> #N/A | J11: =MATCH(Data!J11,$A$1:$A$5,0) -> #N/A | K11: =MATCH(Data!K12,$A$1:$A$5,0) -> #N/A | L11: =MATCH(Data!L12,$A$1:$A$5,0) -> #N/A | M11: =MATCH(Data!M12,$A$1:$A$5,0) -> #N/A | N11: =MATCH(Data!N12,$A$1:$A$5,0) -> #N/A | O11: =MATCH(Data!O12,$A$1:$A$5,0) -> #N/A | P11: =MATCH(Data!P12,$A$1:$A$5,0) -> #N/A | Q11: =MATCH(Data!Q12,$A$1:$A$5,0) -> #N/A | R11: =MATCH(Data!R12,$A$1:$A$5,0) -> 4 | ... Y11: =MATCH(Data!Y12,$A$1:$A$5,0) -> 4 | Z11: =SUM(F11:Y11) -> #N/A
